<?xml version="1.0"?>
<robot name="/Users/yoshidakouji/program/robot_arm/UR3e.urdf" xmlns:xacro="http://ros.org/wiki/xacro">
  <link name="base_link">
    <visual>
      <origin xyz="0 0 0.045" rpy="-3.141592 0 0"/>
      <geometry>
        <cylinder radius="0.064" length="0.09"/>
      </geometry>
    </visual>
    <collision>
      <origin xyz="0 0 0.045" rpy="-3.141592 0 0"/>
      <geometry>
        <cylinder radius="0.064" length="0.09"/>
      </geometry>
    </collision>
  </link>
  <joint name="shoulder_pan_joint" type="revolute">
    <parent link="base_link"/>
    <child link="shoulder_link"/>
    <axis xyz="0 0 1"/>
    <limit effort="330" lower="-6.28319" upper="6.28319" velocity="3.14"/>
    <origin xyz="0 0 0.152" rpy="0 0 0.000006"/>
  </joint>
  <link name="shoulder_link">
    <visual>
      <origin xyz="0 0 -0.003" rpy="-3.141592 0 0"/>
      <geometry>
        <cylinder radius="0.046" length="0.121"/>
      </geometry>
    </visual>
    <collision>
      <origin xyz="0 0 -0.003" rpy="-3.141592 0 0"/>
      <geometry>
        <cylinder radius="0.046" length="0.121"/>
      </geometry>
    </collision>
    <visual>
      <origin xyz="0 0.03 0" rpy="-1.570796 0 0"/>
      <geometry>
        <cylinder radius="0.045" length="0.066"/>
      </geometry>
    </visual>
    <collision>
      <origin xyz="0 0.03 0" rpy="-1.570796 0 0"/>
      <geometry>
        <cylinder radius="0.045" length="0.066"/>
      </geometry>
    </collision>
  </link>
  <joint name="shoulder_lift_joint" type="revolute">
    <parent link="shoulder_link"/>
    <child link="upper_arm_link"/>
    <axis xyz="0 1 0"/>
    <limit effort="330" lower="-6.28319" upper="6.28319" velocity="3.14"/>
    <origin xyz="0 0.12 0" rpy="0 0.000808 0"/>
  </joint>
  <link name="upper_arm_link">
    <visual>
      <origin xyz="0 0 0.035" rpy="-3.141592 0 0"/>
      <geometry>
        <cylinder radius="0.046" length="0.073"/>
      </geometry>
    </visual>
    <collision>
      <origin xyz="0 0 0.035" rpy="-3.141592 0 0"/>
      <geometry>
        <cylinder radius="0.046" length="0.073"/>
      </geometry>
    </collision>
    <visual>
      <origin xyz="0 0 0.157" rpy="-3.141592 0 0"/>
      <geometry>
        <cylinder radius="0.038" length="0.186"/>
      </geometry>
    </visual>
    <collision>
      <origin xyz="0 0 0.157" rpy="-3.141592 0 0"/>
      <geometry>
        <cylinder radius="0.038" length="0.186"/>
      </geometry>
    </collision>
    <visual>
      <origin xyz="0 0 0" rpy="-1.570796 0 0"/>
      <geometry>
        <cylinder radius="0.046" length="0.119"/>
      </geometry>
    </visual>
    <collision>
      <origin xyz="0 0 0" rpy="-1.570796 0 0"/>
      <geometry>
        <cylinder radius="0.046" length="0.119"/>
      </geometry>
    </collision>
    <visual>
      <origin xyz="0 0.002 0.2435" rpy="-1.570796 0 0"/>
      <geometry>
        <cylinder radius="0.038" length="0.11"/>
      </geometry>
    </visual>
    <collision>
      <origin xyz="0 0.002 0.2435" rpy="-1.570796 0 0"/>
      <geometry>
        <cylinder radius="0.038" length="0.11"/>
      </geometry>
    </collision>
  </link>
  <joint name="elbow_joint" type="revolute">
    <parent link="upper_arm_link"/>
    <child link="forearm_link"/>
    <axis xyz="0 1 0"/>
    <limit effort="150" lower="0.7" upper="2.3" velocity="3.14"/>
    <origin xyz="0 -0.093 0.244" rpy="0 1.570012 0"/>
  </joint>
  <link name="forearm_link">
    <visual>
      <origin xyz="0 0 0.125" rpy="-3.141592 0 0"/>
      <geometry>
        <cylinder radius="0.032" length="0.18"/>
      </geometry>
    </visual>
    <collision>
      <origin xyz="0 0 0.125" rpy="-3.141592 0 0"/>
      <geometry>
        <cylinder radius="0.032" length="0.18"/>
      </geometry>
    </collision>
    <visual>
      <origin xyz="0 0.002 0.213" rpy="-1.570796 0 0"/>
      <geometry>
        <cylinder radius="0.032" length="0.1"/>
      </geometry>
    </visual>
    <collision>
      <origin xyz="0 0.002 0.213" rpy="-1.570796 0 0"/>
      <geometry>
        <cylinder radius="0.032" length="0.1"/>
      </geometry>
    </collision>
    <visual>
      <origin xyz="0 0.05 0" rpy="-1.570796 0 0"/>
      <geometry>
        <cylinder radius="0.037" length="0.05"/>
      </geometry>
    </visual>
    <collision>
      <origin xyz="0 0.05 0" rpy="-1.570796 0 0"/>
      <geometry>
        <cylinder radius="0.037" length="0.05"/>
      </geometry>
    </collision>
    <visual>
      <origin xyz="0 0.05 -0.025" rpy="-1.570796 0 0"/>
      <geometry>
        <sphere radius="0.037"/>
      </geometry>
    </visual>
    <collision>
      <origin xyz="0 0.05 -0.025" rpy="-1.570796 0 0"/>
      <geometry>
        <sphere radius="0.037"/>
      </geometry>
    </collision>
    <visual>
      <origin xyz="0 0.05 0.025" rpy="-1.570796 0 0"/>
      <geometry>
        <sphere radius="0.037"/>
      </geometry>
    </visual>
    <collision>
      <origin xyz="0 0.05 0.025" rpy="-1.570796 0 0"/>
      <geometry>
        <sphere radius="0.037"/>
      </geometry>
    </collision>
    <visual>
      <origin xyz="0 0 0.07" rpy="0 0 0"/>
      <geometry>
        <cylinder radius="0.03" length="0.1"/>
      </geometry>
    </visual>
    <collision>
      <origin xyz="0 0 0.07" rpy="0 0 0"/>
      <geometry>
        <cylinder radius="0.03" length="0.1"/>
      </geometry>
    </collision>
    <visual>
      <origin xyz="0 0.05 0.07" rpy="0 0 0"/>
      <geometry>
        <sphere radius="0.03"/>
      </geometry>
    </visual>
    <collision>
      <origin xyz="0 0.05 0.07" rpy="0 0 0"/>
      <geometry>
        <sphere radius="0.03"/>
      </geometry>
    </collision>
    <visual>
      <origin xyz="0 -0.05 0.07" rpy="0 0 0"/>
      <geometry>
        <sphere radius="0.03"/>
      </geometry>
    </visual>
    <collision>
      <origin xyz="0 -0.05 0.07" rpy="0 0 0"/>
      <geometry>
        <sphere radius="0.03"/>
      </geometry>
    </collision>
  </link>
  <joint name="wrist_1_joint" type="revolute">
    <parent link="forearm_link"/>
    <child link="wrist_1_link"/>
    <axis xyz="0 1 0"/>
    <limit effort="54" lower="-6.28319" upper="6.28319" velocity="6.28"/>
    <origin xyz="0 0 0.213" rpy="0 0.000798 0"/>
  </joint>
  <link name="wrist_1_link">
    <visual>
      <origin xyz="0 0.075 0" rpy="-1.570796 0 0"/>
      <geometry>
        <cylinder radius="0.032" length="0.064"/>
      </geometry>
    </visual>
    <collision>
      <origin xyz="0 0.075 0" rpy="-1.570796 0 0"/>
      <geometry>
        <cylinder radius="0.032" length="0.064"/>
      </geometry>
    </collision>
    <visual>
      <origin xyz="0 0.104 0.003" rpy="3.141592 0 0"/>
      <geometry>
        <cylinder radius="0.033" length="0.1"/>
      </geometry>
    </visual>
    <collision>
      <origin xyz="0 0.104 0.003" rpy="3.141592 0 0"/>
      <geometry>
        <cylinder radius="0.033" length="0.1"/>
      </geometry>
    </collision>
  </link>
  <joint name="wrist_2_joint" type="revolute">
    <parent link="wrist_1_link"/>
    <child link="wrist_2_link"/>
    <axis xyz="0 0 1"/>
    <limit effort="54" lower="-3" upper="6.28319" velocity="6.28"/>
    <origin xyz="0 0.104 0" rpy="0 0 -1.57"/>
  </joint>
  <link name="wrist_2_link">
    <visual>
      <origin xyz="0 0.002 0.0854" rpy="-1.570796 0 0"/>
      <geometry>
        <cylinder radius="0.032" length="0.097"/>
      </geometry>
    </visual>
    <collision>
      <origin xyz="0 0.002 0.0854" rpy="-1.570796 0 0"/>
      <geometry>
        <cylinder radius="0.032" length="0.097"/>
      </geometry>
    </collision>
    <visual>
      <origin xyz="0 0 0.0636" rpy="-3.141592 0 0"/>
      <geometry>
        <cylinder radius="0.032" length="0.043"/>
      </geometry>
    </visual>
    <collision>
      <origin xyz="0 0 0.0636" rpy="-3.141592 0 0"/>
      <geometry>
        <cylinder radius="0.032" length="0.043"/>
      </geometry>
    </collision>
  </link>
  <joint name="wrist_3_joint" type="revolute">
    <parent link="wrist_2_link"/>
    <child link="wrist_3_link"/>
    <axis xyz="0 1 0"/>
    <limit effort="54" lower="-6.28319" upper="6.28319" velocity="6.28"/>
    <origin xyz="0 0 0.085" rpy="0 0 0"/>
  </joint>
  <link name="wrist_3_link">
    <visual>
      <origin xyz="0 0.07 0" rpy="-1.570796 0 0"/>
      <geometry>
        <cylinder radius="0.032" length="0.044"/>
      </geometry>
    </visual>
    <collision>
      <origin xyz="0 0.07 0" rpy="-1.570796 0 0"/>
      <geometry>
        <cylinder radius="0.032" length="0.044"/>
      </geometry>
    </collision>
  </link>
  <link name="distance sensor">
  </link>
  <joint name="wrist_3_link_distance sensor_joint" type="fixed">
    <parent link="wrist_3_link"/>
    <child link="distance sensor"/>
    <origin xyz="0 0.19 0" rpy="0 0 1.570796"/>
  </joint>
  <link name="ROBOTIQ 3f Gripper">
    <visual>
      <origin xyz="0 -0.029 0" rpy="0 0 0"/>
      <geometry>
        <cylinder radius="0.023" length="0.05"/>
      </geometry>
    </visual>
    <collision>
      <origin xyz="0 -0.029 0" rpy="0 0 0"/>
      <geometry>
        <cylinder radius="0.023" length="0.05"/>
      </geometry>
    </collision>
    <visual>
      <origin xyz="0 0.005 0" rpy="0 0 0"/>
      <geometry>
        <box size="0.126 0.093 0.13"/>
      </geometry>
    </visual>
    <collision>
      <origin xyz="0 0.005 0" rpy="0 0 0"/>
      <geometry>
        <box size="0.126 0.093 0.13"/>
      </geometry>
    </collision>
  </link>
  <joint name="wrist_3_link_ROBOTIQ 3f Gripper_joint" type="fixed">
    <parent link="wrist_3_link"/>
    <child link="ROBOTIQ 3f Gripper"/>
    <origin xyz="0 0.13 0" rpy="0 0 0"/>
  </joint>
  <joint name="finger_middle_joint_1" type="revolute">
    <parent link="ROBOTIQ 3f Gripper"/>
    <child link="finger_middle_link_1"/>
    <axis xyz="0 0 1"/>
    <limit effort="100" lower="0.0495" upper="1.2218" velocity="100"/>
    <origin xyz="0.045516 0.0414 0" rpy="0 0 1.57"/>
  </joint>
  <link name="finger_middle_link_1">
    <visual>
      <origin xyz="0.01231 -0.02039 0" rpy="0 0 -0.467371"/>
      <geometry>
        <box size="0.091 0.038 0.032"/>
      </geometry>
    </visual>
    <collision>
      <origin xyz="0.01231 -0.02039 0" rpy="0 0 -0.467371"/>
      <geometry>
        <box size="0.091 0.038 0.032"/>
      </geometry>
    </collision>
  </link>
  <joint name="finger_middle_joint_2" type="revolute">
    <parent link="finger_middle_link_1"/>
    <child link="finger_middle_link_2"/>
    <axis xyz="0 0 1"/>
    <limit effort="100" lower="0" upper="1.5708" velocity="100"/>
    <origin xyz="0.05 -0.028 0" rpy="0 0 -0.52"/>
  </joint>
  <link name="finger_middle_link_2">
    <visual>
      <origin xyz="0.02694 -0.008952 0" rpy="0 0 -0.012556"/>
      <geometry>
        <box size="0.04 0.032 0.032"/>
      </geometry>
    </visual>
    <collision>
      <origin xyz="0.02694 -0.008952 0" rpy="0 0 -0.012556"/>
      <geometry>
        <box size="0.04 0.032 0.032"/>
      </geometry>
    </collision>
  </link>
  <joint name="finger_middle_joint_3" type="revolute">
    <parent link="finger_middle_link_2"/>
    <child link="finger_middle_link_3"/>
    <axis xyz="0 0 1"/>
    <limit effort="100" lower="-1.2217" upper="-0.0523" velocity="100"/>
    <origin xyz="0.039 0 0" rpy="0 0 0"/>
  </joint>
  <link name="finger_middle_link_3">
    <visual>
      <origin xyz="0.018 0.00913 0" rpy="0 0 0.520259"/>
      <geometry>
        <box size="0.035 0.018 0.032"/>
      </geometry>
    </visual>
    <collision>
      <origin xyz="0.018 0.00913 0" rpy="0 0 0.520259"/>
      <geometry>
        <box size="0.035 0.018 0.032"/>
      </geometry>
    </collision>
  </link>
  <joint name="palm_finger_2_joint" type="revolute">
    <parent link="ROBOTIQ 3f Gripper"/>
    <child link="finger_2_link_0"/>
    <axis xyz="0 1 -0.000007"/>
    <limit effort="100" lower="-0.192" upper="0.1784" velocity="100"/>
    <origin xyz="-0.0455 0.0214 -0.036" rpy="3.141592 -0.000008 1.571593"/>
  </joint>
  <link name="finger_2_link_0">
    <visual>
      <origin xyz="0.007 0.006 0" rpy="0 0 0"/>
      <geometry>
        <box size="0.04 0.04 0.032"/>
      </geometry>
    </visual>
    <collision>
      <origin xyz="0.007 0.006 0" rpy="0 0 0"/>
      <geometry>
        <box size="0.04 0.04 0.032"/>
      </geometry>
    </collision>
  </link>
  <joint name="finger_2_joint_1" type="revolute">
    <parent link="finger_2_link_0"/>
    <child link="finger_2_link_1"/>
    <axis xyz="0 0 1"/>
    <limit effort="100" lower="0.0495" upper="1.2218" velocity="100"/>
    <origin xyz="0.02 0 0" rpy="0 0 0"/>
  </joint>
  <link name="finger_2_link_1">
    <visual>
      <origin xyz="0.012315 -0.02039 0" rpy="0 0 -0.467371"/>
      <geometry>
        <box size="0.091 0.038 0.032"/>
      </geometry>
    </visual>
    <collision>
      <origin xyz="0.012315 -0.02039 0" rpy="0 0 -0.467371"/>
      <geometry>
        <box size="0.091 0.038 0.032"/>
      </geometry>
    </collision>
  </link>
  <joint name="finger_2_joint_2" type="revolute">
    <parent link="finger_2_link_1"/>
    <child link="finger_2_link_2"/>
    <axis xyz="0 0 1"/>
    <limit effort="100" lower="0" upper="1.5708" velocity="100"/>
    <origin xyz="0.05 -0.028 0" rpy="0 0 -0.52"/>
  </joint>
  <link name="finger_2_link_2">
    <visual>
      <origin xyz="0.02694 -0.00895 0" rpy="0 0 -0.012556"/>
      <geometry>
        <box size="0.04 0.032 0.032"/>
      </geometry>
    </visual>
    <collision>
      <origin xyz="0.02694 -0.00895 0" rpy="0 0 -0.012556"/>
      <geometry>
        <box size="0.04 0.032 0.032"/>
      </geometry>
    </collision>
  </link>
  <joint name="finger_2_joint_3" type="revolute">
    <parent link="finger_2_link_2"/>
    <child link="finger_2_link_3"/>
    <axis xyz="0 0 1"/>
    <limit effort="100" lower="-1.2217" upper="-0.0523" velocity="100"/>
    <origin xyz="0.039 0 0" rpy="0 0 0"/>
  </joint>
  <link name="finger_2_link_3">
    <visual>
      <origin xyz="0.018 0.00913 0" rpy="0 0 0.520259"/>
      <geometry>
        <box size="0.035 0.018 0.032"/>
      </geometry>
    </visual>
    <collision>
      <origin xyz="0.018 0.00913 0" rpy="0 0 0.520259"/>
      <geometry>
        <box size="0.035 0.018 0.032"/>
      </geometry>
    </collision>
  </link>
  <joint name="palm_finger_1_joint" type="revolute">
    <parent link="ROBOTIQ 3f Gripper"/>
    <child link="finger_1_link_0"/>
    <axis xyz="0 1 -0.000007"/>
    <limit effort="100" lower="-0.1784" upper="0.192" velocity="100"/>
    <origin xyz="-0.0455 0.0214 0.036" rpy="3.141592 -0.000008 1.571593"/>
  </joint>
  <link name="finger_1_link_0">
    <visual>
      <origin xyz="0.007 0.006 0" rpy="0 0 0"/>
      <geometry>
        <box size="0.04 0.04 0.032"/>
      </geometry>
    </visual>
    <collision>
      <origin xyz="0.007 0.006 0" rpy="0 0 0"/>
      <geometry>
        <box size="0.04 0.04 0.032"/>
      </geometry>
    </collision>
  </link>
  <joint name="finger_1_joint_1" type="revolute">
    <parent link="finger_1_link_0"/>
    <child link="finger_1_link_1"/>
    <axis xyz="0 0 1"/>
    <limit effort="100" lower="0.0495" upper="1.2218" velocity="100"/>
    <origin xyz="0.02 0 0" rpy="0 0 0"/>
  </joint>
  <link name="finger_1_link_1">
    <visual>
      <origin xyz="0.012316 -0.02039 0" rpy="0 0 -0.467371"/>
      <geometry>
        <box size="0.091 0.038 0.032"/>
      </geometry>
    </visual>
    <collision>
      <origin xyz="0.012316 -0.02039 0" rpy="0 0 -0.467371"/>
      <geometry>
        <box size="0.091 0.038 0.032"/>
      </geometry>
    </collision>
  </link>
  <joint name="finger_1_joint_2" type="revolute">
    <parent link="finger_1_link_1"/>
    <child link="finger_1_link_2"/>
    <axis xyz="0 0 1"/>
    <limit effort="100" lower="0" upper="1.5708" velocity="100"/>
    <origin xyz="0.05 -0.028 0" rpy="0 0 -0.52"/>
  </joint>
  <link name="finger_1_link_2">
    <visual>
      <origin xyz="0.02694 -0.00895 0" rpy="0 0 -0.012556"/>
      <geometry>
        <box size="0.04 0.032 0.032"/>
      </geometry>
    </visual>
    <collision>
      <origin xyz="0.02694 -0.00895 0" rpy="0 0 -0.012556"/>
      <geometry>
        <box size="0.04 0.032 0.032"/>
      </geometry>
    </collision>
  </link>
  <joint name="finger_1_joint_3" type="revolute">
    <parent link="finger_1_link_2"/>
    <child link="finger_1_link_3"/>
    <axis xyz="0 0 1"/>
    <limit effort="100" lower="-1.2217" upper="-0.0523" velocity="100"/>
    <origin xyz="0.039 0 0" rpy="0 0 0"/>
  </joint>
  <link name="finger_1_link_3">
    <visual>
      <origin xyz="0.018004 0.009133 0" rpy="0 0 0.520259"/>
      <geometry>
        <box size="0.035 0.018 0.032"/>
      </geometry>
    </visual>
    <collision>
      <origin xyz="0.018004 0.009133 0" rpy="0 0 0.520259"/>
      <geometry>
        <box size="0.035 0.018 0.032"/>
      </geometry>
    </collision>
  </link>
</robot>
